<robot
  name="HMMR">
  <link
    name="base_link">
    <inertial>
      <origin
        xyz="-0.29285 0 -1.1102E-16"
        rpy="0 0 0" />
      <mass
        value="100" />
      <inertia
        ixx="13.041"
        ixy="5.7234E-16"
        ixz="-9.4857E-16"
        iyy="10.742"
        iyz="8.2239E-16"
        izz="22.623" />
    </inertial>
    <visual>
      <origin
        xyz="0 0 0"
        rpy="0 0 0" />
      <geometry>
        <mesh
          filename="package://HMMR/meshes/base_link.STL" />
      </geometry>
      <material
        name="">
        <color
          rgba="0.79216 0.81961 0.93333 1" />
      </material>
    </visual>
    <collision>
      <origin
        xyz="0 0 0"
        rpy="0 0 0" />
      <geometry>
        <mesh
          filename="package://HMMR/meshes/base_link.STL" />
      </geometry>
    </collision>
  </link>
  <link
    name="L1">
    <inertial>
      <origin
        xyz="-0.37454 0.26079 0"
        rpy="0 0 0" />
      <mass
        value="50" />
      <inertia
        ixx="2.2546"
        ixy="1.7267"
        ixz="3.434E-17"
        iyy="3.5322"
        iyz="-3.7342E-19"
        izz="3.9584" />
    </inertial>
    <visual>
      <origin
        xyz="0 0 0"
        rpy="0 0 0" />
      <geometry>
        <mesh
          filename="package://HMMR/meshes/L1.STL" />
      </geometry>
      <material
        name="">
        <color
          rgba="0.79216 0.81961 0.93333 1" />
      </material>
    </visual>
    <collision>
      <origin
        xyz="0 0 0"
        rpy="0 0 0" />
      <geometry>
        <mesh
          filename="package://HMMR/meshes/L1.STL" />
      </geometry>
    </collision>
  </link>
  <joint
    name="Revolute1"
    type="revolute">
    <origin
      xyz="0 0 0"
      rpy="1.5708 -0.60823 4.2634E-17" />
    <parent
      link="base_link" />
    <child
      link="L1" />
    <axis
      xyz="0 0 1" />
    <limit
      effort="0"
      velocity="0" />
  </joint>
  <link
    name="L2">
    <inertial>
      <origin
        xyz="0.21428 0.052924 0"
        rpy="0 0 0" />
      <mass
        value="15" />
      <inertia
        ixx="0.056466"
        ixy="0.026975"
        ixz="-6.195E-19"
        iyy="0.58936"
        iyz="-1.0894E-18"
        izz="0.58948" />
    </inertial>
    <visual>
      <origin
        xyz="0 0 0"
        rpy="0 0 0" />
      <geometry>
        <mesh
          filename="package://HMMR/meshes/L2.STL" />
      </geometry>
      <material
        name="">
        <color
          rgba="0.79216 0.81961 0.93333 1" />
      </material>
    </visual>
    <collision>
      <origin
        xyz="0 0 0"
        rpy="0 0 0" />
      <geometry>
        <mesh
          filename="package://HMMR/meshes/L2.STL" />
      </geometry>
    </collision>
  </link>
  <joint
    name="Revolute2"
    type="revolute">
    <origin
      xyz="-0.64066 0.36851 0"
      rpy="0 0 -0.55778" />
    <parent
      link="L1" />
    <child
      link="L2" />
    <axis
      xyz="0 0 1" />
    <limit
      effort="0"
      velocity="0" />
  </joint>
  <link
    name="Wheel_FR">
    <inertial>
      <origin
        xyz="0 0 1.1102E-16"
        rpy="0 0 0" />
      <mass
        value="12" />
      <inertia
        ixx="0.10139"
        ixy="0"
        ixz="4.6777E-34"
        iyy="0.10139"
        iyz="-3.3318E-34"
        izz="0.12069" />
    </inertial>
    <visual>
      <origin
        xyz="0 0 0"
        rpy="0 0 0" />
      <geometry>
        <mesh
          filename="package://HMMR/meshes/Wheel_FR.STL" />
      </geometry>
      <material
        name="">
        <color
          rgba="0.79216 0.81961 0.93333 1" />
      </material>
    </visual>
    <collision>
      <origin
        xyz="0 0 0"
        rpy="0 0 0" />
      <geometry>
        <mesh
          filename="package://HMMR/meshes/Wheel_FR.STL" />
      </geometry>
    </collision>
  </link>
  <joint
    name="W_rev_FR"
    type="revolute">
    <origin
      xyz="0 -0.35 0"
      rpy="1.5708 0 0" />
    <parent
      link="base_link" />
    <child
      link="Wheel_FR" />
    <axis
      xyz="0 0 1" />
    <limit
      effort="0"
      velocity="0" />
  </joint>
  <link
    name="Wheel_FL">
    <inertial>
      <origin
        xyz="-1.1102E-16 5.5511E-17 0"
        rpy="0 0 0" />
      <mass
        value="12" />
      <inertia
        ixx="0.10139"
        ixy="-3.2526E-19"
        ixz="-2.8907E-18"
        iyy="0.10139"
        iyz="5.4155E-20"
        izz="0.12069" />
    </inertial>
    <visual>
      <origin
        xyz="0 0 0"
        rpy="0 0 0" />
      <geometry>
        <mesh
          filename="package://HMMR/meshes/Wheel_FL.STL" />
      </geometry>
      <material
        name="">
        <color
          rgba="0.79216 0.81961 0.93333 1" />
      </material>
    </visual>
    <collision>
      <origin
        xyz="0 0 0"
        rpy="0 0 0" />
      <geometry>
        <mesh
          filename="package://HMMR/meshes/Wheel_FL.STL" />
      </geometry>
    </collision>
  </link>
  <joint
    name="W_rev_FL"
    type="revolute">
    <origin
      xyz="0 0.35 0"
      rpy="1.5708 -0.018732 1.1471E-18" />
    <parent
      link="base_link" />
    <child
      link="Wheel_FL" />
    <axis
      xyz="0 0 1" />
    <limit
      effort="0"
      velocity="0" />
  </joint>
  <link
    name="Wheel_BR">
    <inertial>
      <origin
        xyz="1.3878E-17 0 -1.1102E-16"
        rpy="0 0 0" />
      <mass
        value="12" />
      <inertia
        ixx="0.10139"
        ixy="1.2529E-49"
        ixz="1.118E-33"
        iyy="0.10139"
        iyz="-3.3318E-34"
        izz="0.12069" />
    </inertial>
    <visual>
      <origin
        xyz="0 0 0"
        rpy="0 0 0" />
      <geometry>
        <mesh
          filename="package://HMMR/meshes/Wheel_BR.STL" />
      </geometry>
      <material
        name="">
        <color
          rgba="0.79216 0.81961 0.93333 1" />
      </material>
    </visual>
    <collision>
      <origin
        xyz="0 0 0"
        rpy="0 0 0" />
      <geometry>
        <mesh
          filename="package://HMMR/meshes/Wheel_BR.STL" />
      </geometry>
    </collision>
  </link>
  <joint
    name="W_rev_BR"
    type="revolute">
    <origin
      xyz="-0.75 -0.35 0"
      rpy="1.5708 0 0" />
    <parent
      link="base_link" />
    <child
      link="Wheel_BR" />
    <axis
      xyz="0 0 1" />
    <limit
      effort="0"
      velocity="0" />
  </joint>
  <link
    name="Wheel_BL">
    <inertial>
      <origin
        xyz="0 0 0"
        rpy="0 0 0" />
      <mass
        value="12" />
      <inertia
        ixx="0.10139"
        ixy="-6.9389E-18"
        ixz="6.1242E-19"
        iyy="0.10139"
        iyz="-1.3095E-18"
        izz="0.12069" />
    </inertial>
    <visual>
      <origin
        xyz="0 0 0"
        rpy="0 0 0" />
      <geometry>
        <mesh
          filename="package://HMMR/meshes/Wheel_BL.STL" />
      </geometry>
      <material
        name="">
        <color
          rgba="0.79216 0.81961 0.93333 1" />
      </material>
    </visual>
    <collision>
      <origin
        xyz="0 0 0"
        rpy="0 0 0" />
      <geometry>
        <mesh
          filename="package://HMMR/meshes/Wheel_BL.STL" />
      </geometry>
    </collision>
  </link>
  <joint
    name="W_rev_BL"
    type="revolute">
    <origin
      xyz="-0.75 0.35 0"
      rpy="1.5708 0.43747 -2.8637E-17" />
    <parent
      link="base_link" />
    <child
      link="Wheel_BL" />
    <axis
      xyz="0 0 1" />
    <limit
      effort="0"
      velocity="0" />
  </joint>
</robot>